[2024-04-03T14:42:00.466+0000] {taskinstance.py:1979} INFO - Dependencies all met for dep_context=non-requeueable deps ti=<TaskInstance: example-docker-operator-dag.print_message manual__2024-04-03T14:41:59.547354+00:00 [queued]>
[2024-04-03T14:42:00.472+0000] {taskinstance.py:1979} INFO - Dependencies all met for dep_context=requeueable deps ti=<TaskInstance: example-docker-operator-dag.print_message manual__2024-04-03T14:41:59.547354+00:00 [queued]>
[2024-04-03T14:42:00.472+0000] {taskinstance.py:2193} INFO - Starting attempt 1 of 1
[2024-04-03T14:42:00.479+0000] {taskinstance.py:2217} INFO - Executing <Task(DockerOperator): print_message> on 2024-04-03 14:41:59.547354+00:00
[2024-04-03T14:42:00.482+0000] {standard_task_runner.py:60} INFO - Started process 372 to run task
[2024-04-03T14:42:00.484+0000] {standard_task_runner.py:87} INFO - Running: ['***', 'tasks', 'run', 'example-docker-operator-dag', 'print_message', 'manual__2024-04-03T14:41:59.547354+00:00', '--job-id', '23', '--raw', '--subdir', 'DAGS_FOLDER/example_docker_operator_dag.py', '--cfg-path', '/tmp/tmpvybnq7cw']
[2024-04-03T14:42:00.485+0000] {standard_task_runner.py:88} INFO - Job 23: Subtask print_message
[2024-04-03T14:42:00.513+0000] {task_command.py:423} INFO - Running <TaskInstance: example-docker-operator-dag.print_message manual__2024-04-03T14:41:59.547354+00:00 [running]> on host 42f8d4163c95
[2024-04-03T14:42:00.564+0000] {taskinstance.py:2513} INFO - Exporting env vars: AIRFLOW_CTX_DAG_OWNER='***' AIRFLOW_CTX_DAG_ID='example-docker-operator-dag' AIRFLOW_CTX_TASK_ID='print_message' AIRFLOW_CTX_EXECUTION_DATE='2024-04-03T14:41:59.547354+00:00' AIRFLOW_CTX_TRY_NUMBER='1' AIRFLOW_CTX_DAG_RUN_ID='manual__2024-04-03T14:41:59.547354+00:00'
[2024-04-03T14:42:00.575+0000] {docker.py:359} INFO - Starting docker container from image docker-operator-etl:1.0
[2024-04-03T14:42:00.592+0000] {taskinstance.py:2731} ERROR - Task failed with exception
Traceback (most recent call last):
  File "/home/airflow/.local/lib/python3.8/site-packages/docker/api/client.py", line 265, in _raise_for_status
    response.raise_for_status()
  File "/home/airflow/.local/lib/python3.8/site-packages/requests/models.py", line 1021, in raise_for_status
    raise HTTPError(http_error_msg, response=self)
requests.exceptions.HTTPError: 400 Client Error: Bad Request for url: http+docker://localhost/v1.44/containers/create?name=example-DURACELL-docker-operator-dag__print_message__eae6a17385

The above exception was the direct cause of the following exception:

Traceback (most recent call last):
  File "/home/airflow/.local/lib/python3.8/site-packages/airflow/models/taskinstance.py", line 444, in _execute_task
    result = _execute_callable(context=context, **execute_callable_kwargs)
  File "/home/airflow/.local/lib/python3.8/site-packages/airflow/models/taskinstance.py", line 414, in _execute_callable
    return execute_callable(context=context, **execute_callable_kwargs)
  File "/home/airflow/.local/lib/python3.8/site-packages/airflow/providers/docker/operators/docker.py", line 502, in execute
    return self._run_image()
  File "/home/airflow/.local/lib/python3.8/site-packages/airflow/providers/docker/operators/docker.py", line 376, in _run_image
    return self._run_image_with_mounts(self.mounts, add_tmp_variable=False)
  File "/home/airflow/.local/lib/python3.8/site-packages/airflow/providers/docker/operators/docker.py", line 391, in _run_image_with_mounts
    self.container = self.cli.create_container(
  File "/home/airflow/.local/lib/python3.8/site-packages/docker/api/container.py", line 439, in create_container
    return self.create_container_from_config(config, name, platform)
  File "/home/airflow/.local/lib/python3.8/site-packages/docker/api/container.py", line 456, in create_container_from_config
    return self._result(res, True)
  File "/home/airflow/.local/lib/python3.8/site-packages/docker/api/client.py", line 271, in _result
    self._raise_for_status(response)
  File "/home/airflow/.local/lib/python3.8/site-packages/docker/api/client.py", line 267, in _raise_for_status
    raise create_api_error_from_http_exception(e) from e
  File "/home/airflow/.local/lib/python3.8/site-packages/docker/errors.py", line 39, in create_api_error_from_http_exception
    raise cls(e, response=response, explanation=explanation) from e
docker.errors.APIError: 400 Client Error for http+docker://localhost/v1.44/containers/create?name=example-DURACELL-docker-operator-dag__print_message__eae6a17385: Bad Request ("create /home/jobs/docker-airflow-operator/src: "/home/jobs/docker-airflow-operator/src" includes invalid characters for a local volume name, only "[a-zA-Z0-9][a-zA-Z0-9_.-]" are allowed. If you intended to pass a host directory, use absolute path")
[2024-04-03T14:42:00.599+0000] {taskinstance.py:1149} INFO - Marking task as FAILED. dag_id=example-docker-operator-dag, task_id=print_message, execution_date=20240403T144159, start_date=20240403T144200, end_date=20240403T144200
[2024-04-03T14:42:00.607+0000] {standard_task_runner.py:107} ERROR - Failed to execute job 23 for task print_message (400 Client Error for http+docker://localhost/v1.44/containers/create?name=example-DURACELL-docker-operator-dag__print_message__eae6a17385: Bad Request ("create /home/jobs/docker-airflow-operator/src: "/home/jobs/docker-airflow-operator/src" includes invalid characters for a local volume name, only "[a-zA-Z0-9][a-zA-Z0-9_.-]" are allowed. If you intended to pass a host directory, use absolute path"); 372)
[2024-04-03T14:42:00.616+0000] {local_task_job_runner.py:234} INFO - Task exited with return code 1
[2024-04-03T14:42:00.631+0000] {taskinstance.py:3312} INFO - 0 downstream tasks scheduled from follow-on schedule check
