[2024-04-02T23:06:49.163+0000] {taskinstance.py:1979} INFO - Dependencies all met for dep_context=non-requeueable deps ti=<TaskInstance: example-docker-operator-dag.print_message manual__2024-04-02T23:06:47.812954+00:00 [queued]>
[2024-04-02T23:06:49.169+0000] {taskinstance.py:1979} INFO - Dependencies all met for dep_context=requeueable deps ti=<TaskInstance: example-docker-operator-dag.print_message manual__2024-04-02T23:06:47.812954+00:00 [queued]>
[2024-04-02T23:06:49.169+0000] {taskinstance.py:2193} INFO - Starting attempt 1 of 1
[2024-04-02T23:06:49.177+0000] {taskinstance.py:2217} INFO - Executing <Task(DockerOperator): print_message> on 2024-04-02 23:06:47.812954+00:00
[2024-04-02T23:06:49.181+0000] {standard_task_runner.py:60} INFO - Started process 160 to run task
[2024-04-02T23:06:49.183+0000] {standard_task_runner.py:87} INFO - Running: ['***', 'tasks', 'run', 'example-docker-operator-dag', 'print_message', 'manual__2024-04-02T23:06:47.812954+00:00', '--job-id', '5', '--raw', '--subdir', 'DAGS_FOLDER/example_docker_operator_dag.py', '--cfg-path', '/tmp/tmpu9y27hwq']
[2024-04-02T23:06:49.183+0000] {standard_task_runner.py:88} INFO - Job 5: Subtask print_message
[2024-04-02T23:06:49.221+0000] {task_command.py:423} INFO - Running <TaskInstance: example-docker-operator-dag.print_message manual__2024-04-02T23:06:47.812954+00:00 [running]> on host bf549e430153
[2024-04-02T23:06:49.272+0000] {taskinstance.py:2513} INFO - Exporting env vars: AIRFLOW_CTX_DAG_OWNER='***' AIRFLOW_CTX_DAG_ID='example-docker-operator-dag' AIRFLOW_CTX_TASK_ID='print_message' AIRFLOW_CTX_EXECUTION_DATE='2024-04-02T23:06:47.812954+00:00' AIRFLOW_CTX_TRY_NUMBER='1' AIRFLOW_CTX_DAG_RUN_ID='manual__2024-04-02T23:06:47.812954+00:00'
[2024-04-02T23:06:49.282+0000] {docker.py:486} INFO - Pulling docker image docker-operator-etl:latest
[2024-04-02T23:06:56.487+0000] {taskinstance.py:2731} ERROR - Task failed with exception
Traceback (most recent call last):
  File "/home/airflow/.local/lib/python3.8/site-packages/docker/api/client.py", line 265, in _raise_for_status
    response.raise_for_status()
  File "/home/airflow/.local/lib/python3.8/site-packages/requests/models.py", line 1021, in raise_for_status
    raise HTTPError(http_error_msg, response=self)
requests.exceptions.HTTPError: 404 Client Error: Not Found for url: http+docker://localhost/v1.44/images/create?tag=latest&fromImage=docker-operator-etl

The above exception was the direct cause of the following exception:

Traceback (most recent call last):
  File "/home/airflow/.local/lib/python3.8/site-packages/airflow/models/taskinstance.py", line 444, in _execute_task
    result = _execute_callable(context=context, **execute_callable_kwargs)
  File "/home/airflow/.local/lib/python3.8/site-packages/airflow/models/taskinstance.py", line 414, in _execute_callable
    return execute_callable(context=context, **execute_callable_kwargs)
  File "/home/airflow/.local/lib/python3.8/site-packages/airflow/providers/docker/operators/docker.py", line 488, in execute
    for output in self.cli.pull(self.image, stream=True, decode=True):
  File "/home/airflow/.local/lib/python3.8/site-packages/docker/api/image.py", line 429, in pull
    self._raise_for_status(response)
  File "/home/airflow/.local/lib/python3.8/site-packages/docker/api/client.py", line 267, in _raise_for_status
    raise create_api_error_from_http_exception(e) from e
  File "/home/airflow/.local/lib/python3.8/site-packages/docker/errors.py", line 39, in create_api_error_from_http_exception
    raise cls(e, response=response, explanation=explanation) from e
docker.errors.ImageNotFound: 404 Client Error for http+docker://localhost/v1.44/images/create?tag=latest&fromImage=docker-operator-etl: Not Found ("pull access denied for docker-operator-etl, repository does not exist or may require 'docker login': denied: requested access to the resource is denied")
[2024-04-02T23:06:56.496+0000] {taskinstance.py:1149} INFO - Marking task as FAILED. dag_id=example-docker-operator-dag, task_id=print_message, execution_date=20240402T230647, start_date=20240402T230649, end_date=20240402T230656
[2024-04-02T23:06:56.506+0000] {standard_task_runner.py:107} ERROR - Failed to execute job 5 for task print_message (404 Client Error for http+docker://localhost/v1.44/images/create?tag=latest&fromImage=docker-operator-etl: Not Found ("pull access denied for docker-operator-etl, repository does not exist or may require 'docker login': denied: requested access to the resource is denied"); 160)
[2024-04-02T23:06:56.511+0000] {local_task_job_runner.py:234} INFO - Task exited with return code 1
[2024-04-02T23:06:56.523+0000] {taskinstance.py:3312} INFO - 0 downstream tasks scheduled from follow-on schedule check
